2019-02-15 09:52:14,780 [ALWAYS] mongo_connector.connector:50 - Starting mongo-connector version: 3.1.1
2019-02-15 09:52:14,780 [ALWAYS] mongo_connector.connector:50 - Python version: 3.6.7 (v3.6.7:6ec5cf24b7, Oct 20 2018, 13:35:33) [MSC v.1900 64 bit (AMD64)]
2019-02-15 09:52:14,780 [ALWAYS] mongo_connector.connector:50 - Platform: Windows-10-10.0.17134-SP0
2019-02-15 09:52:14,780 [ALWAYS] mongo_connector.connector:50 - pymongo version: 3.7.2
2019-02-15 09:52:14,780 [WARNING] mongo_connector.connector:170 - MongoConnector: Can't find C:\Users\Adobe\Documents\Projects\auntie_server\guides\oplog.timestamp, attempting to create an empty progress log
2019-02-15 09:52:14,794 [ALWAYS] mongo_connector.connector:50 - Source MongoDB version: 4.0.1
2019-02-15 09:52:14,794 [ALWAYS] mongo_connector.connector:50 - Target DocManager: mongo_connector.doc_managers.elastic2_doc_manager version: 1.0.0
2019-02-15 09:58:08,986 [ERROR] mongo_connector.oplog_manager:349 - Cursor closed due to an exception. Will attempt to reconnect.
Traceback (most recent call last):
  File "c:\users\adobe\appdata\local\programs\python\python36\lib\site-packages\mongo_connector\oplog_manager.py", line 245, in run
    for n, entry in enumerate(cursor):
  File "c:\users\adobe\appdata\local\programs\python\python36\lib\site-packages\pymongo\cursor.py", line 1189, in next
    if len(self.__data) or self._refresh():
  File "c:\users\adobe\appdata\local\programs\python\python36\lib\site-packages\pymongo\cursor.py", line 1126, in _refresh
    self.__send_message(g)
  File "c:\users\adobe\appdata\local\programs\python\python36\lib\site-packages\pymongo\cursor.py", line 931, in __send_message
    operation, exhaust=self.__exhaust, address=self.__address)
  File "c:\users\adobe\appdata\local\programs\python\python36\lib\site-packages\pymongo\mongo_client.py", line 1145, in _send_message_with_response
    exhaust)
  File "c:\users\adobe\appdata\local\programs\python\python36\lib\site-packages\pymongo\mongo_client.py", line 1156, in _reset_on_error
    return func(*args, **kwargs)
  File "c:\users\adobe\appdata\local\programs\python\python36\lib\site-packages\pymongo\server.py", line 106, in send_message_with_response
    reply = sock_info.receive_message(request_id)
  File "c:\users\adobe\appdata\local\programs\python\python36\lib\site-packages\pymongo\pool.py", line 612, in receive_message
    self._raise_connection_failure(error)
  File "c:\users\adobe\appdata\local\programs\python\python36\lib\site-packages\pymongo\pool.py", line 745, in _raise_connection_failure
    raise error
  File "c:\users\adobe\appdata\local\programs\python\python36\lib\site-packages\pymongo\pool.py", line 610, in receive_message
    self.max_message_size)
  File "c:\users\adobe\appdata\local\programs\python\python36\lib\site-packages\pymongo\network.py", line 173, in receive_message
    _receive_data_on_socket(sock, 16))
  File "c:\users\adobe\appdata\local\programs\python\python36\lib\site-packages\pymongo\network.py", line 238, in _receive_data_on_socket
    raise AutoReconnect("connection closed")
pymongo.errors.AutoReconnect: connection closed
2019-02-15 15:26:37,543 [ALWAYS] mongo_connector.connector:50 - Starting mongo-connector version: 3.1.1
2019-02-15 15:26:37,543 [ALWAYS] mongo_connector.connector:50 - Python version: 3.6.7 (v3.6.7:6ec5cf24b7, Oct 20 2018, 13:35:33) [MSC v.1900 64 bit (AMD64)]
2019-02-15 15:26:37,544 [ALWAYS] mongo_connector.connector:50 - Platform: Windows-10-10.0.17134-SP0
2019-02-15 15:26:37,544 [ALWAYS] mongo_connector.connector:50 - pymongo version: 3.7.2
2019-02-15 15:26:37,559 [ALWAYS] mongo_connector.connector:50 - Source MongoDB version: 4.0.1
2019-02-15 15:26:37,559 [ALWAYS] mongo_connector.connector:50 - Target DocManager: mongo_connector.doc_managers.elastic2_doc_manager version: 1.0.0
